{
 "cells": [
  {
   "cell_type": "code",
   "execution_count": null,
   "metadata": {},
   "outputs": [],
   "source": [
    "import xml.etree.ElementTree as ET\n",
    "from xlwt import Workbook \n",
    "import xlwt \n",
    "#Workbook is created \n",
    "wb = Workbook() \n",
    "import pandas as pd\n",
    "#add_sheet is used to create sheet. \n",
    "# sheet1 = wb.add_sheet('Sheet 1', cell_overwrite_ok=True) \n",
    "tree = ET.parse('E:/offc_work/anderson/xmltcsv/Quick Quote-20191025T162809Z-001/B_13436.xml_2019_08_21_13_44_50_529.xml')\n",
    "root = tree.getroot()\n",
    "\n",
    "q,q1,q2,q3,q4,q5,q6,q7,q8,q9,q10,q11,q12=[],[],[],[],[],[],[],[],[],[],[],[],[]\n",
    "\n",
    "for child in root.findall('./LineItemMasters/LineItemMaster/LineItems/LineItem'):\n",
    "    print(child.tag)\n",
    "\n",
    "    a=child.find(\"LineItemNumber\").text\n",
    "    print(a)\n",
    "    q=q+[a]\n",
    "\n",
    "    b=child.find(\"LineItemName\").text\n",
    "    q1=q1+[b]\n",
    "\n",
    "    c=child.find(\"ConfiguratorType\").text\n",
    "    q2=q2+[c]\n",
    "\n",
    "    d=child.find(\"ConfiguratorPKVersion\").text\n",
    "    q3=q3+[d]\n",
    "\n",
    "    f=child.find(\"LineItemID\").text\n",
    "    q5=q5+[f]\n",
    "\n",
    "    g=child.find(\"ParentLineItemID\").text\n",
    "    q6=q6+[g]\n",
    "\n",
    "    h=child.find(\"LinePrice\").text\n",
    "    q7=q7+[h]\n",
    "\n",
    "    i=child.find(\"Cost\").text\n",
    "    q8=q8+[i]\n",
    "\n",
    "    j=child.find(\"Description\").text\n",
    "    q9=q9+[j]\n",
    "\n",
    "    k=child.find(\"Quantity\").text\n",
    "    q10=q10+[k]\n",
    "\n",
    "    m=child.find(\"LongDescription\").text\n",
    "    q12=q12+[m]\n",
    "\n",
    "for child in root.findall('./LineItemMasters/LineItemMaster/LineItems/LineItem/LICustomDataXML'):\n",
    "\tprint(child.tag)\n",
    "\tl=child.find(\"EDIDescription\").text\n",
    "\tq11=q11+[l]\n",
    "df=pd.DataFrame()\n",
    "df['LineItemNumber']=q\n",
    "df['LineItemName']=q1\n",
    "df['ConfiguratorType']=q2\n",
    "df['ConfiguratorPKVersion']=q3\n",
    "\n",
    "df['LineItemID']=q5\n",
    "df['ParentLineItemID']=q6\n",
    "df['LinePrice']=q7\n",
    "df['Cost']=q8\n",
    "df['Description']=q9\n",
    "df['Quantity']=q10\n",
    "df['EDIDescription']=q11\n",
    "df['LongDescription']=q12\n",
    "print(df['LongDescription'])\n",
    "df.to_excel('E:/offc_work/anderson/xmltcsv/Quick Quote-20191025T162809Z-001/B_13436.xml_2019_08_21_13_44_50_529.xlsx') \n"
   ]
  },
  {
   "cell_type": "code",
   "execution_count": 1,
   "metadata": {},
   "outputs": [],
   "source": [
    "import pandas as pd\n",
    "\n",
    "df1 = pd.read_excel('Quick Quote-20191025T162809Z-001/B_13436.xml_2019_08_21_13_44_50_529.xlsx')\n",
    "df2 = pd.read_excel('Quick Quote-20191025T162809Z-001/C_13556.xml_2019_09_27_15_06_28_086.xlsx')"
   ]
  },
  {
   "cell_type": "code",
   "execution_count": 4,
   "metadata": {},
   "outputs": [
    {
     "data": {
      "text/plain": [
       "0     {#1} |AWDESC=400 Awning, Mull using Number Wid...\n",
       "1     ATT TO {#1} |AWDESC=Hardware: PSA   Classic Se...\n",
       "2     ATT TO {#1} |AWDESC=Hardware: PSA   Classic Se...\n",
       "3     ATT TO {#1} |AWDESC=Hardware: PSA   Classic Se...\n",
       "4     ATT TO {#1} |AWDESC=Hardware: PSA   Classic Se...\n",
       "5     ATT TO {#1} |AWDESC=Exterior Trim: PSA  98.75 ...\n",
       "6     {#2} |AWDESC=A Series Patio Doors 2 Panel-FWG,...\n",
       "7     ATT TO {#2} |AWDESC=Safety and Security 1:  PN...\n",
       "8     ATT TO {#2} |AWDESC=Safety and Security 1 miss...\n",
       "9     ATT TO {#2} |AWDESC=Trim Set 1: FWGD Stationar...\n",
       "10    ATT TO {#2} |AWDESC=Auxiliary Foot Lock 1: FWG...\n",
       "11    ATT TO {#2} |AWDESC=Exterior Keyed Lock 1: FWG...\n",
       "12    ATT TO {#2} |AWDESC=Insect Screen 1: A Series ...\n",
       "13    ATT TO {#2} |AWDESC=Threshold: FWGD8080 Maple ...\n",
       "14    ATT TO {#2} |AWDESC=Panel 1:  Left Slab  FWGD8...\n",
       "15    ATT TO {#2} |AWDESC=Panel 2:  Right Slab  FWGD...\n",
       "16    ATT TO {#2} |AWDESC=Exterior Trim: [Configurat...\n",
       "17    ATT TO {#2} |AWDESC=Decorative Trim: [Configur...\n",
       "18    ATT TO {#2} |AWDESC=Extension Jamb 1: [Configu...\n",
       "19    {#3} |AWDESC=400 Double-Hung Bay, Mull using N...\n",
       "20    ATT TO {#3} |AWDESC=Sash Lift: TW Hand Lift Tr...\n",
       "21    ATT TO {#3} |AWDESC=Insect Screen 1: 400 Serie...\n",
       "22    ATT TO {#3} |AWDESC=Sash Lift: TW Hand Lift Tr...\n",
       "23    ATT TO {#3} |AWDESC=Insect Screen 1: 400 Serie...\n",
       "24    ATT TO {#3} |AWDESC=Sash Lift: TW Hand Lift Tr...\n",
       "25    ATT TO {#3} |AWDESC=Insect Screen 1: 400 Serie...\n",
       "26    ATT TO {#3} |AWDESC=Extension Jamb 1: TW TW45-...\n",
       "27    ATT TO {#3} |AWDESC=Head and Seat Board: TW Fr...\n",
       "28    ATT TO {#3} |AWDESC=Angle Bay/Bow Supports: Fr...\n",
       "29    ATT TO {#3} |AWDESC=Top Auxiliary Casing: TW45...\n",
       "                            ...                        \n",
       "32    ATT TO {#4} |AWDESC=Grille 1: C56-BOW RIG Colo...\n",
       "33    ATT TO {#4} |AWDESC=Grille 1: C56-BOW RIG Colo...\n",
       "34    ATT TO {#4} |AWDESC=Hardware: PSC   Contempora...\n",
       "35    ATT TO {#4} |AWDESC=Insect Screen 1: 400 Serie...\n",
       "36    ATT TO {#4} |AWDESC=Grille 1: C56-BOW RIG Colo...\n",
       "37    ATT TO {#4} |AWDESC=Grille 1: C56-BOW RIG Colo...\n",
       "38    ATT TO {#4} |AWDESC=Grille 1: C56-BOW RIG Colo...\n",
       "39    ATT TO {#4} |AWDESC=Extension Jamb 1: PSC C56-...\n",
       "40    ATT TO {#4} |AWDESC=Head and Seat Board: PSC F...\n",
       "41    ATT TO {#4} |AWDESC=Angle Bay/Bow Supports: Fr...\n",
       "42    ATT TO {#4} |AWDESC=Top Auxiliary Casing: C56-...\n",
       "43    {#5} |AWDESC=100 Single Casement-CW, Parts/Acc...\n",
       "44    {#6} |AWDESC=400 Specialty Equal Leg Arch, 48 ...\n",
       "45    ATT TO {#6} |AWDESC=Exterior Trim: [Configurat...\n",
       "46    ATT TO {#6} |AWDESC=Arch Casing: AFC22 2 1/4\" ...\n",
       "47    {#7} |AWDESC=100 Series Specialty Trapezoid, 5...\n",
       "48    {#8} |AWDESC=400 Double-Hung, Mulled Units, Eq...\n",
       "49    ATT TO {#8} |AWDESC=400 Specialty Half Circle-...\n",
       "50    ATT TO {#8} |AWDESC=Safety and Security 1:  PN...\n",
       "51    ATT TO {#8} |AWDESC=Arch Casing: TW3462 2 1/4\"...\n",
       "52    ATT TO {#8} |AWDESC=Join Mull Material: 400 Se...\n",
       "53    ATT TO {#8} |AWDESC=Mull Casing: TW, 74, Horiz...\n",
       "54    {#9} |AWDESC=400 Twin Vertical Awning, 24 1/8 ...\n",
       "55    ATT TO {#9} |AWDESC=Hardware: PSA   Contempora...\n",
       "56    ATT TO {#9} |AWDESC=Insect Screen 1: 400 Serie...\n",
       "57    ATT TO {#9} |AWDESC=Exterior Trim: [Configurat...\n",
       "58    ATT TO {#9} |AWDESC=Decorative Trim: [Configur...\n",
       "59    {#10} |AWDESC=400 Triple Horizontal Awning, 84...\n",
       "60    ATT TO {#10} |AWDESC=Exterior Trim: [Configura...\n",
       "61    ATT TO {#10} |AWDESC=Decorative Trim: [Configu...\n",
       "Name: EDIDescription, Length: 62, dtype: object"
      ]
     },
     "execution_count": 4,
     "metadata": {},
     "output_type": "execute_result"
    }
   ],
   "source": [
    "df1[\"EDIDescription\"]"
   ]
  },
  {
   "cell_type": "code",
   "execution_count": 5,
   "metadata": {},
   "outputs": [
    {
     "name": "stderr",
     "output_type": "stream",
     "text": [
      "ERROR:root:Internal Python error in the inspect module.\n",
      "Below is the traceback from this internal error.\n",
      "\n",
      "ERROR:root:Internal Python error in the inspect module.\n",
      "Below is the traceback from this internal error.\n",
      "\n"
     ]
    },
    {
     "name": "stdout",
     "output_type": "stream",
     "text": [
      "Traceback (most recent call last):\n",
      "  File \"c:\\python35\\lib\\site-packages\\pandas\\core\\indexes\\base.py\", line 2657, in get_loc\n",
      "    return self._engine.get_loc(key)\n",
      "  File \"pandas\\_libs\\index.pyx\", line 108, in pandas._libs.index.IndexEngine.get_loc\n",
      "  File \"pandas\\_libs\\index.pyx\", line 132, in pandas._libs.index.IndexEngine.get_loc\n",
      "  File \"pandas\\_libs\\hashtable_class_helper.pxi\", line 1601, in pandas._libs.hashtable.PyObjectHashTable.get_item\n",
      "  File \"pandas\\_libs\\hashtable_class_helper.pxi\", line 1608, in pandas._libs.hashtable.PyObjectHashTable.get_item\n",
      "KeyError: 'UID'\n",
      "\n",
      "During handling of the above exception, another exception occurred:\n",
      "\n",
      "Traceback (most recent call last):\n",
      "  File \"c:\\python35\\lib\\site-packages\\IPython\\core\\interactiveshell.py\", line 2862, in run_code\n",
      "    exec(code_obj, self.user_global_ns, self.user_ns)\n",
      "  File \"<ipython-input-5-dfcdf2985ec1>\", line 7, in <module>\n",
      "    df1['UID'][i]=df\n",
      "  File \"c:\\python35\\lib\\site-packages\\pandas\\core\\frame.py\", line 2927, in __getitem__\n",
      "    indexer = self.columns.get_loc(key)\n",
      "  File \"c:\\python35\\lib\\site-packages\\pandas\\core\\indexes\\base.py\", line 2659, in get_loc\n",
      "    return self._engine.get_loc(self._maybe_cast_indexer(key))\n",
      "  File \"pandas\\_libs\\index.pyx\", line 108, in pandas._libs.index.IndexEngine.get_loc\n",
      "  File \"pandas\\_libs\\index.pyx\", line 132, in pandas._libs.index.IndexEngine.get_loc\n",
      "  File \"pandas\\_libs\\hashtable_class_helper.pxi\", line 1601, in pandas._libs.hashtable.PyObjectHashTable.get_item\n",
      "  File \"pandas\\_libs\\hashtable_class_helper.pxi\", line 1608, in pandas._libs.hashtable.PyObjectHashTable.get_item\n",
      "KeyError: 'UID'\n",
      "\n",
      "During handling of the above exception, another exception occurred:\n",
      "\n",
      "Traceback (most recent call last):\n",
      "  File \"c:\\python35\\lib\\site-packages\\IPython\\core\\interactiveshell.py\", line 1806, in showtraceback\n",
      "    stb = value._render_traceback_()\n",
      "AttributeError: 'KeyError' object has no attribute '_render_traceback_'\n",
      "\n",
      "During handling of the above exception, another exception occurred:\n",
      "\n",
      "Traceback (most recent call last):\n",
      "  File \"c:\\python35\\lib\\site-packages\\IPython\\core\\ultratb.py\", line 1090, in get_records\n",
      "    return _fixed_getinnerframes(etb, number_of_lines_of_context, tb_offset)\n",
      "  File \"c:\\python35\\lib\\site-packages\\IPython\\core\\ultratb.py\", line 311, in wrapped\n",
      "    return f(*args, **kwargs)\n",
      "  File \"c:\\python35\\lib\\site-packages\\IPython\\core\\ultratb.py\", line 345, in _fixed_getinnerframes\n",
      "    records = fix_frame_records_filenames(inspect.getinnerframes(etb, context))\n",
      "  File \"C:\\Python35\\Lib\\inspect.py\", line 1453, in getinnerframes\n",
      "    frameinfo = (tb.tb_frame,) + getframeinfo(tb, context)\n",
      "  File \"C:\\Python35\\Lib\\inspect.py\", line 1410, in getframeinfo\n",
      "    filename = getsourcefile(frame) or getfile(frame)\n",
      "  File \"C:\\Python35\\Lib\\inspect.py\", line 672, in getsourcefile\n",
      "    if getattr(getmodule(object, filename), '__loader__', None) is not None:\n",
      "  File \"C:\\Python35\\Lib\\inspect.py\", line 709, in getmodule\n",
      "    if ismodule(module) and hasattr(module, '__file__'):\n",
      "  File \"c:\\python35\\lib\\site-packages\\py\\_vendored_packages\\apipkg.py\", line 195, in __getattribute__\n",
      "    return getattr(getmod(), name)\n",
      "  File \"c:\\python35\\lib\\site-packages\\py\\_vendored_packages\\apipkg.py\", line 179, in getmod\n",
      "    x = importobj(modpath, None)\n",
      "  File \"c:\\python35\\lib\\site-packages\\py\\_vendored_packages\\apipkg.py\", line 69, in importobj\n",
      "    module = __import__(modpath, None, None, ['__doc__'])\n",
      "  File \"c:\\python35\\lib\\site-packages\\pytest.py\", line 8, in <module>\n",
      "    from _pytest.assertion import register_assert_rewrite\n",
      "  File \"c:\\python35\\lib\\site-packages\\_pytest\\assertion\\__init__.py\", line 13, in <module>\n",
      "    from _pytest.assertion import rewrite\n",
      "  File \"c:\\python35\\lib\\site-packages\\_pytest\\assertion\\rewrite.py\", line 24, in <module>\n",
      "    from _pytest.assertion import util\n",
      "  File \"c:\\python35\\lib\\site-packages\\_pytest\\assertion\\util.py\", line 11, in <module>\n",
      "    import _pytest._code\n",
      "  File \"c:\\python35\\lib\\site-packages\\_pytest\\_code\\__init__.py\", line 7, in <module>\n",
      "    from .code import Code  # noqa\n",
      "  File \"c:\\python35\\lib\\site-packages\\_pytest\\_code\\code.py\", line 15, in <module>\n",
      "    import pluggy\n",
      "  File \"c:\\python35\\lib\\site-packages\\pluggy\\__init__.py\", line 16, in <module>\n",
      "    from .manager import PluginManager, PluginValidationError\n",
      "  File \"c:\\python35\\lib\\site-packages\\pluggy\\manager.py\", line 6, in <module>\n",
      "    import importlib_metadata\n",
      "  File \"c:\\python35\\lib\\site-packages\\importlib_metadata\\__init__.py\", line 471, in <module>\n",
      "    __version__ = version(__name__)\n",
      "  File \"c:\\python35\\lib\\site-packages\\importlib_metadata\\__init__.py\", line 438, in version\n",
      "    return distribution(package).version\n",
      "  File \"c:\\python35\\lib\\site-packages\\importlib_metadata\\__init__.py\", line 411, in distribution\n",
      "    return Distribution.from_name(package)\n",
      "  File \"c:\\python35\\lib\\site-packages\\importlib_metadata\\__init__.py\", line 180, in from_name\n",
      "    dist = next(dists, None)\n",
      "  File \"c:\\python35\\lib\\site-packages\\importlib_metadata\\__init__.py\", line 366, in <genexpr>\n",
      "    for path in map(cls._switch_path, paths)\n",
      "  File \"c:\\python35\\lib\\site-packages\\importlib_metadata\\__init__.py\", line 382, in _search_path\n",
      "    if not root.is_dir():\n",
      "  File \"C:\\Python35\\Lib\\pathlib.py\", line 1318, in is_dir\n",
      "    return S_ISDIR(self.stat().st_mode)\n",
      "  File \"C:\\Python35\\Lib\\pathlib.py\", line 1126, in stat\n",
      "    return self._accessor.stat(self)\n",
      "  File \"C:\\Python35\\Lib\\pathlib.py\", line 371, in wrapped\n",
      "    return strfunc(str(pathobj), *args)\n",
      "OSError: [WinError 123] The filename, directory name, or volume label syntax is incorrect: 'C:\\\\Users\\\\dmutta\\\\Downloads\\\\shogun-shogun_6.1.3\\\\src\\\\interfaces\\\\python:C:\\\\Python35'\n",
      "Traceback (most recent call last):\n",
      "  File \"c:\\python35\\lib\\site-packages\\pandas\\core\\indexes\\base.py\", line 2657, in get_loc\n",
      "    return self._engine.get_loc(key)\n",
      "  File \"pandas\\_libs\\index.pyx\", line 108, in pandas._libs.index.IndexEngine.get_loc\n",
      "  File \"pandas\\_libs\\index.pyx\", line 132, in pandas._libs.index.IndexEngine.get_loc\n"
     ]
    },
    {
     "name": "stderr",
     "output_type": "stream",
     "text": [
      "ERROR:root:Internal Python error in the inspect module.\n",
      "Below is the traceback from this internal error.\n",
      "\n"
     ]
    },
    {
     "name": "stdout",
     "output_type": "stream",
     "text": [
      "  File \"pandas\\_libs\\hashtable_class_helper.pxi\", line 1601, in pandas._libs.hashtable.PyObjectHashTable.get_item\n",
      "  File \"pandas\\_libs\\hashtable_class_helper.pxi\", line 1608, in pandas._libs.hashtable.PyObjectHashTable.get_item\n",
      "KeyError: 'UID'\n",
      "\n",
      "During handling of the above exception, another exception occurred:\n",
      "\n",
      "Traceback (most recent call last):\n",
      "  File \"c:\\python35\\lib\\site-packages\\IPython\\core\\interactiveshell.py\", line 2862, in run_code\n",
      "    exec(code_obj, self.user_global_ns, self.user_ns)\n",
      "  File \"<ipython-input-5-dfcdf2985ec1>\", line 7, in <module>\n",
      "    df1['UID'][i]=df\n",
      "  File \"c:\\python35\\lib\\site-packages\\pandas\\core\\frame.py\", line 2927, in __getitem__\n",
      "    indexer = self.columns.get_loc(key)\n",
      "  File \"c:\\python35\\lib\\site-packages\\pandas\\core\\indexes\\base.py\", line 2659, in get_loc\n",
      "    return self._engine.get_loc(self._maybe_cast_indexer(key))\n",
      "  File \"pandas\\_libs\\index.pyx\", line 108, in pandas._libs.index.IndexEngine.get_loc\n",
      "  File \"pandas\\_libs\\index.pyx\", line 132, in pandas._libs.index.IndexEngine.get_loc\n",
      "  File \"pandas\\_libs\\hashtable_class_helper.pxi\", line 1601, in pandas._libs.hashtable.PyObjectHashTable.get_item\n",
      "  File \"pandas\\_libs\\hashtable_class_helper.pxi\", line 1608, in pandas._libs.hashtable.PyObjectHashTable.get_item\n",
      "KeyError: 'UID'\n",
      "\n",
      "During handling of the above exception, another exception occurred:\n",
      "\n",
      "Traceback (most recent call last):\n",
      "  File \"c:\\python35\\lib\\site-packages\\IPython\\core\\interactiveshell.py\", line 1806, in showtraceback\n",
      "    stb = value._render_traceback_()\n",
      "AttributeError: 'KeyError' object has no attribute '_render_traceback_'\n",
      "\n",
      "During handling of the above exception, another exception occurred:\n",
      "\n",
      "Traceback (most recent call last):\n",
      "  File \"c:\\python35\\lib\\site-packages\\IPython\\core\\interactiveshell.py\", line 2802, in run_ast_nodes\n",
      "    if self.run_code(code, result):\n",
      "  File \"c:\\python35\\lib\\site-packages\\IPython\\core\\interactiveshell.py\", line 2879, in run_code\n",
      "    self.showtraceback(running_compiled_code=True)\n",
      "  File \"c:\\python35\\lib\\site-packages\\IPython\\core\\interactiveshell.py\", line 1809, in showtraceback\n",
      "    value, tb, tb_offset=tb_offset)\n",
      "  File \"c:\\python35\\lib\\site-packages\\IPython\\core\\ultratb.py\", line 1371, in structured_traceback\n",
      "    self, etype, value, tb, tb_offset, number_of_lines_of_context)\n",
      "  File \"c:\\python35\\lib\\site-packages\\IPython\\core\\ultratb.py\", line 1279, in structured_traceback\n",
      "    self, etype, value, tb, tb_offset, number_of_lines_of_context\n",
      "  File \"c:\\python35\\lib\\site-packages\\IPython\\core\\ultratb.py\", line 1140, in structured_traceback\n",
      "    formatted_exceptions += self.prepare_chained_exception_message(evalue.__cause__)\n",
      "TypeError: Can't convert 'list' object to str implicitly\n",
      "\n",
      "During handling of the above exception, another exception occurred:\n",
      "\n",
      "Traceback (most recent call last):\n",
      "  File \"c:\\python35\\lib\\site-packages\\IPython\\core\\interactiveshell.py\", line 1806, in showtraceback\n",
      "    stb = value._render_traceback_()\n",
      "AttributeError: 'TypeError' object has no attribute '_render_traceback_'\n",
      "\n",
      "During handling of the above exception, another exception occurred:\n",
      "\n",
      "Traceback (most recent call last):\n",
      "  File \"c:\\python35\\lib\\site-packages\\IPython\\core\\ultratb.py\", line 1090, in get_records\n",
      "    return _fixed_getinnerframes(etb, number_of_lines_of_context, tb_offset)\n",
      "  File \"c:\\python35\\lib\\site-packages\\IPython\\core\\ultratb.py\", line 311, in wrapped\n",
      "    return f(*args, **kwargs)\n",
      "  File \"c:\\python35\\lib\\site-packages\\IPython\\core\\ultratb.py\", line 345, in _fixed_getinnerframes\n",
      "    records = fix_frame_records_filenames(inspect.getinnerframes(etb, context))\n",
      "  File \"C:\\Python35\\Lib\\inspect.py\", line 1453, in getinnerframes\n",
      "    frameinfo = (tb.tb_frame,) + getframeinfo(tb, context)\n",
      "  File \"C:\\Python35\\Lib\\inspect.py\", line 1410, in getframeinfo\n",
      "    filename = getsourcefile(frame) or getfile(frame)\n",
      "  File \"C:\\Python35\\Lib\\inspect.py\", line 672, in getsourcefile\n",
      "    if getattr(getmodule(object, filename), '__loader__', None) is not None:\n",
      "  File \"C:\\Python35\\Lib\\inspect.py\", line 709, in getmodule\n",
      "    if ismodule(module) and hasattr(module, '__file__'):\n",
      "  File \"c:\\python35\\lib\\site-packages\\py\\_vendored_packages\\apipkg.py\", line 195, in __getattribute__\n",
      "    return getattr(getmod(), name)\n",
      "  File \"c:\\python35\\lib\\site-packages\\py\\_vendored_packages\\apipkg.py\", line 179, in getmod\n",
      "    x = importobj(modpath, None)\n",
      "  File \"c:\\python35\\lib\\site-packages\\py\\_vendored_packages\\apipkg.py\", line 69, in importobj\n",
      "    module = __import__(modpath, None, None, ['__doc__'])\n",
      "  File \"c:\\python35\\lib\\site-packages\\pytest.py\", line 8, in <module>\n",
      "    from _pytest.assertion import register_assert_rewrite\n",
      "  File \"c:\\python35\\lib\\site-packages\\_pytest\\assertion\\__init__.py\", line 13, in <module>\n",
      "    from _pytest.assertion import rewrite\n",
      "  File \"c:\\python35\\lib\\site-packages\\_pytest\\assertion\\rewrite.py\", line 24, in <module>\n",
      "    from _pytest.assertion import util\n",
      "  File \"c:\\python35\\lib\\site-packages\\_pytest\\assertion\\util.py\", line 11, in <module>\n",
      "    import _pytest._code\n",
      "  File \"c:\\python35\\lib\\site-packages\\_pytest\\_code\\__init__.py\", line 7, in <module>\n",
      "    from .code import Code  # noqa\n",
      "  File \"c:\\python35\\lib\\site-packages\\_pytest\\_code\\code.py\", line 15, in <module>\n",
      "    import pluggy\n",
      "  File \"c:\\python35\\lib\\site-packages\\pluggy\\__init__.py\", line 16, in <module>\n",
      "    from .manager import PluginManager, PluginValidationError\n",
      "  File \"c:\\python35\\lib\\site-packages\\pluggy\\manager.py\", line 6, in <module>\n",
      "    import importlib_metadata\n",
      "  File \"c:\\python35\\lib\\site-packages\\importlib_metadata\\__init__.py\", line 471, in <module>\n",
      "    __version__ = version(__name__)\n",
      "  File \"c:\\python35\\lib\\site-packages\\importlib_metadata\\__init__.py\", line 438, in version\n",
      "    return distribution(package).version\n",
      "  File \"c:\\python35\\lib\\site-packages\\importlib_metadata\\__init__.py\", line 411, in distribution\n",
      "    return Distribution.from_name(package)\n",
      "  File \"c:\\python35\\lib\\site-packages\\importlib_metadata\\__init__.py\", line 180, in from_name\n",
      "    dist = next(dists, None)\n",
      "  File \"c:\\python35\\lib\\site-packages\\importlib_metadata\\__init__.py\", line 366, in <genexpr>\n",
      "    for path in map(cls._switch_path, paths)\n",
      "  File \"c:\\python35\\lib\\site-packages\\importlib_metadata\\__init__.py\", line 382, in _search_path\n",
      "    if not root.is_dir():\n",
      "  File \"C:\\Python35\\Lib\\pathlib.py\", line 1318, in is_dir\n",
      "    return S_ISDIR(self.stat().st_mode)\n",
      "  File \"C:\\Python35\\Lib\\pathlib.py\", line 1126, in stat\n",
      "    return self._accessor.stat(self)\n",
      "  File \"C:\\Python35\\Lib\\pathlib.py\", line 371, in wrapped\n",
      "    return strfunc(str(pathobj), *args)\n",
      "OSError: [WinError 123] The filename, directory name, or volume label syntax is incorrect: 'C:\\\\Users\\\\dmutta\\\\Downloads\\\\shogun-shogun_6.1.3\\\\src\\\\interfaces\\\\python:C:\\\\Python35'\n",
      "Traceback (most recent call last):\n",
      "  File \"c:\\python35\\lib\\site-packages\\pandas\\core\\indexes\\base.py\", line 2657, in get_loc\n",
      "    return self._engine.get_loc(key)\n",
      "  File \"pandas\\_libs\\index.pyx\", line 108, in pandas._libs.index.IndexEngine.get_loc\n",
      "  File \"pandas\\_libs\\index.pyx\", line 132, in pandas._libs.index.IndexEngine.get_loc\n",
      "  File \"pandas\\_libs\\hashtable_class_helper.pxi\", line 1601, in pandas._libs.hashtable.PyObjectHashTable.get_item\n",
      "  File \"pandas\\_libs\\hashtable_class_helper.pxi\", line 1608, in pandas._libs.hashtable.PyObjectHashTable.get_item\n",
      "KeyError: 'UID'\n",
      "\n",
      "During handling of the above exception, another exception occurred:\n",
      "\n",
      "Traceback (most recent call last):\n",
      "  File \"c:\\python35\\lib\\site-packages\\IPython\\core\\interactiveshell.py\", line 2862, in run_code\n",
      "    exec(code_obj, self.user_global_ns, self.user_ns)\n",
      "  File \"<ipython-input-5-dfcdf2985ec1>\", line 7, in <module>\n",
      "    df1['UID'][i]=df\n",
      "  File \"c:\\python35\\lib\\site-packages\\pandas\\core\\frame.py\", line 2927, in __getitem__\n",
      "    indexer = self.columns.get_loc(key)\n",
      "  File \"c:\\python35\\lib\\site-packages\\pandas\\core\\indexes\\base.py\", line 2659, in get_loc\n",
      "    return self._engine.get_loc(self._maybe_cast_indexer(key))\n",
      "  File \"pandas\\_libs\\index.pyx\", line 108, in pandas._libs.index.IndexEngine.get_loc\n",
      "  File \"pandas\\_libs\\index.pyx\", line 132, in pandas._libs.index.IndexEngine.get_loc\n",
      "  File \"pandas\\_libs\\hashtable_class_helper.pxi\", line 1601, in pandas._libs.hashtable.PyObjectHashTable.get_item\n",
      "  File \"pandas\\_libs\\hashtable_class_helper.pxi\", line 1608, in pandas._libs.hashtable.PyObjectHashTable.get_item\n",
      "KeyError: 'UID'\n",
      "\n",
      "During handling of the above exception, another exception occurred:\n",
      "\n",
      "Traceback (most recent call last):\n",
      "  File \"c:\\python35\\lib\\site-packages\\IPython\\core\\interactiveshell.py\", line 1806, in showtraceback\n",
      "    stb = value._render_traceback_()\n",
      "AttributeError: 'KeyError' object has no attribute '_render_traceback_'\n",
      "\n",
      "During handling of the above exception, another exception occurred:\n",
      "\n",
      "Traceback (most recent call last):\n",
      "  File \"c:\\python35\\lib\\site-packages\\IPython\\core\\interactiveshell.py\", line 2802, in run_ast_nodes\n",
      "    if self.run_code(code, result):\n",
      "  File \"c:\\python35\\lib\\site-packages\\IPython\\core\\interactiveshell.py\", line 2879, in run_code\n",
      "    self.showtraceback(running_compiled_code=True)\n",
      "  File \"c:\\python35\\lib\\site-packages\\IPython\\core\\interactiveshell.py\", line 1809, in showtraceback\n",
      "    value, tb, tb_offset=tb_offset)\n",
      "  File \"c:\\python35\\lib\\site-packages\\IPython\\core\\ultratb.py\", line 1371, in structured_traceback\n",
      "    self, etype, value, tb, tb_offset, number_of_lines_of_context)\n",
      "  File \"c:\\python35\\lib\\site-packages\\IPython\\core\\ultratb.py\", line 1279, in structured_traceback\n",
      "    self, etype, value, tb, tb_offset, number_of_lines_of_context\n",
      "  File \"c:\\python35\\lib\\site-packages\\IPython\\core\\ultratb.py\", line 1140, in structured_traceback\n",
      "    formatted_exceptions += self.prepare_chained_exception_message(evalue.__cause__)\n",
      "TypeError: Can't convert 'list' object to str implicitly\n",
      "\n",
      "During handling of the above exception, another exception occurred:\n",
      "\n",
      "Traceback (most recent call last):\n",
      "  File \"c:\\python35\\lib\\site-packages\\IPython\\core\\interactiveshell.py\", line 1806, in showtraceback\n",
      "    stb = value._render_traceback_()\n",
      "AttributeError: 'TypeError' object has no attribute '_render_traceback_'\n",
      "\n",
      "During handling of the above exception, another exception occurred:\n",
      "\n",
      "Traceback (most recent call last):\n",
      "  File \"c:\\python35\\lib\\site-packages\\IPython\\core\\ultratb.py\", line 1090, in get_records\n",
      "    return _fixed_getinnerframes(etb, number_of_lines_of_context, tb_offset)\n",
      "  File \"c:\\python35\\lib\\site-packages\\IPython\\core\\ultratb.py\", line 311, in wrapped\n",
      "    return f(*args, **kwargs)\n",
      "  File \"c:\\python35\\lib\\site-packages\\IPython\\core\\ultratb.py\", line 345, in _fixed_getinnerframes\n",
      "    records = fix_frame_records_filenames(inspect.getinnerframes(etb, context))\n",
      "  File \"C:\\Python35\\Lib\\inspect.py\", line 1453, in getinnerframes\n",
      "    frameinfo = (tb.tb_frame,) + getframeinfo(tb, context)\n",
      "  File \"C:\\Python35\\Lib\\inspect.py\", line 1410, in getframeinfo\n",
      "    filename = getsourcefile(frame) or getfile(frame)\n",
      "  File \"C:\\Python35\\Lib\\inspect.py\", line 672, in getsourcefile\n",
      "    if getattr(getmodule(object, filename), '__loader__', None) is not None:\n",
      "  File \"C:\\Python35\\Lib\\inspect.py\", line 709, in getmodule\n",
      "    if ismodule(module) and hasattr(module, '__file__'):\n",
      "  File \"c:\\python35\\lib\\site-packages\\py\\_vendored_packages\\apipkg.py\", line 195, in __getattribute__\n",
      "    return getattr(getmod(), name)\n",
      "  File \"c:\\python35\\lib\\site-packages\\py\\_vendored_packages\\apipkg.py\", line 179, in getmod\n",
      "    x = importobj(modpath, None)\n",
      "  File \"c:\\python35\\lib\\site-packages\\py\\_vendored_packages\\apipkg.py\", line 69, in importobj\n",
      "    module = __import__(modpath, None, None, ['__doc__'])\n",
      "  File \"c:\\python35\\lib\\site-packages\\pytest.py\", line 8, in <module>\n",
      "    from _pytest.assertion import register_assert_rewrite\n",
      "  File \"c:\\python35\\lib\\site-packages\\_pytest\\assertion\\__init__.py\", line 13, in <module>\n",
      "    from _pytest.assertion import rewrite\n",
      "  File \"c:\\python35\\lib\\site-packages\\_pytest\\assertion\\rewrite.py\", line 24, in <module>\n",
      "    from _pytest.assertion import util\n",
      "  File \"c:\\python35\\lib\\site-packages\\_pytest\\assertion\\util.py\", line 11, in <module>\n",
      "    import _pytest._code\n",
      "  File \"c:\\python35\\lib\\site-packages\\_pytest\\_code\\__init__.py\", line 7, in <module>\n",
      "    from .code import Code  # noqa\n",
      "  File \"c:\\python35\\lib\\site-packages\\_pytest\\_code\\code.py\", line 15, in <module>\n",
      "    import pluggy\n",
      "  File \"c:\\python35\\lib\\site-packages\\pluggy\\__init__.py\", line 16, in <module>\n",
      "    from .manager import PluginManager, PluginValidationError\n",
      "  File \"c:\\python35\\lib\\site-packages\\pluggy\\manager.py\", line 6, in <module>\n",
      "    import importlib_metadata\n",
      "  File \"c:\\python35\\lib\\site-packages\\importlib_metadata\\__init__.py\", line 471, in <module>\n",
      "    __version__ = version(__name__)\n",
      "  File \"c:\\python35\\lib\\site-packages\\importlib_metadata\\__init__.py\", line 438, in version\n",
      "    return distribution(package).version\n",
      "  File \"c:\\python35\\lib\\site-packages\\importlib_metadata\\__init__.py\", line 411, in distribution\n",
      "    return Distribution.from_name(package)\n",
      "  File \"c:\\python35\\lib\\site-packages\\importlib_metadata\\__init__.py\", line 180, in from_name\n",
      "    dist = next(dists, None)\n",
      "  File \"c:\\python35\\lib\\site-packages\\importlib_metadata\\__init__.py\", line 366, in <genexpr>\n",
      "    for path in map(cls._switch_path, paths)\n",
      "  File \"c:\\python35\\lib\\site-packages\\importlib_metadata\\__init__.py\", line 382, in _search_path\n",
      "    if not root.is_dir():\n",
      "  File \"C:\\Python35\\Lib\\pathlib.py\", line 1318, in is_dir\n",
      "    return S_ISDIR(self.stat().st_mode)\n",
      "  File \"C:\\Python35\\Lib\\pathlib.py\", line 1126, in stat\n",
      "    return self._accessor.stat(self)\n",
      "  File \"C:\\Python35\\Lib\\pathlib.py\", line 371, in wrapped\n",
      "    return strfunc(str(pathobj), *args)\n",
      "OSError: [WinError 123] The filename, directory name, or volume label syntax is incorrect: 'C:\\\\Users\\\\dmutta\\\\Downloads\\\\shogun-shogun_6.1.3\\\\src\\\\interfaces\\\\python:C:\\\\Python35'\n"
     ]
    },
    {
     "ename": "TypeError",
     "evalue": "Can't convert 'list' object to str implicitly",
     "output_type": "error",
     "traceback": [
      "\u001b[1;31m---------------------------------------------------------------------------\u001b[0m",
      "\nDuring handling of the above exception, another exception occurred:\n",
      "\nDuring handling of the above exception, another exception occurred:\n",
      "\u001b[1;31mAttributeError\u001b[0m                            Traceback (most recent call last)",
      "\u001b[1;32mc:\\python35\\lib\\site-packages\\IPython\\core\\interactiveshell.py\u001b[0m in \u001b[0;36mshowtraceback\u001b[1;34m(self, exc_tuple, filename, tb_offset, exception_only, running_compiled_code)\u001b[0m\n\u001b[0;32m   1805\u001b[0m                         \u001b[1;31m# in the engines. This should return a list of strings.\u001b[0m\u001b[1;33m\u001b[0m\u001b[1;33m\u001b[0m\u001b[0m\n\u001b[1;32m-> 1806\u001b[1;33m                         \u001b[0mstb\u001b[0m \u001b[1;33m=\u001b[0m \u001b[0mvalue\u001b[0m\u001b[1;33m.\u001b[0m\u001b[0m_render_traceback_\u001b[0m\u001b[1;33m(\u001b[0m\u001b[1;33m)\u001b[0m\u001b[1;33m\u001b[0m\u001b[0m\n\u001b[0m\u001b[0;32m   1807\u001b[0m                     \u001b[1;32mexcept\u001b[0m \u001b[0mException\u001b[0m\u001b[1;33m:\u001b[0m\u001b[1;33m\u001b[0m\u001b[0m\n",
      "\u001b[1;31mAttributeError\u001b[0m: 'KeyError' object has no attribute '_render_traceback_'",
      "\nDuring handling of the above exception, another exception occurred:\n",
      "\u001b[1;31mTypeError\u001b[0m                                 Traceback (most recent call last)",
      "\u001b[1;32mc:\\python35\\lib\\site-packages\\IPython\\core\\interactiveshell.py\u001b[0m in \u001b[0;36mrun_code\u001b[1;34m(self, code_obj, result)\u001b[0m\n\u001b[0;32m   2877\u001b[0m             \u001b[1;32mif\u001b[0m \u001b[0mresult\u001b[0m \u001b[1;32mis\u001b[0m \u001b[1;32mnot\u001b[0m \u001b[1;32mNone\u001b[0m\u001b[1;33m:\u001b[0m\u001b[1;33m\u001b[0m\u001b[0m\n\u001b[0;32m   2878\u001b[0m                 \u001b[0mresult\u001b[0m\u001b[1;33m.\u001b[0m\u001b[0merror_in_exec\u001b[0m \u001b[1;33m=\u001b[0m \u001b[0msys\u001b[0m\u001b[1;33m.\u001b[0m\u001b[0mexc_info\u001b[0m\u001b[1;33m(\u001b[0m\u001b[1;33m)\u001b[0m\u001b[1;33m[\u001b[0m\u001b[1;36m1\u001b[0m\u001b[1;33m]\u001b[0m\u001b[1;33m\u001b[0m\u001b[0m\n\u001b[1;32m-> 2879\u001b[1;33m             \u001b[0mself\u001b[0m\u001b[1;33m.\u001b[0m\u001b[0mshowtraceback\u001b[0m\u001b[1;33m(\u001b[0m\u001b[0mrunning_compiled_code\u001b[0m\u001b[1;33m=\u001b[0m\u001b[1;32mTrue\u001b[0m\u001b[1;33m)\u001b[0m\u001b[1;33m\u001b[0m\u001b[0m\n\u001b[0m\u001b[0;32m   2880\u001b[0m         \u001b[1;32melse\u001b[0m\u001b[1;33m:\u001b[0m\u001b[1;33m\u001b[0m\u001b[0m\n\u001b[0;32m   2881\u001b[0m             \u001b[0moutflag\u001b[0m \u001b[1;33m=\u001b[0m \u001b[1;32mFalse\u001b[0m\u001b[1;33m\u001b[0m\u001b[0m\n",
      "\u001b[1;32mc:\\python35\\lib\\site-packages\\IPython\\core\\interactiveshell.py\u001b[0m in \u001b[0;36mshowtraceback\u001b[1;34m(self, exc_tuple, filename, tb_offset, exception_only, running_compiled_code)\u001b[0m\n\u001b[0;32m   1807\u001b[0m                     \u001b[1;32mexcept\u001b[0m \u001b[0mException\u001b[0m\u001b[1;33m:\u001b[0m\u001b[1;33m\u001b[0m\u001b[0m\n\u001b[0;32m   1808\u001b[0m                         stb = self.InteractiveTB.structured_traceback(etype,\n\u001b[1;32m-> 1809\u001b[1;33m                                             value, tb, tb_offset=tb_offset)\n\u001b[0m\u001b[0;32m   1810\u001b[0m \u001b[1;33m\u001b[0m\u001b[0m\n\u001b[0;32m   1811\u001b[0m                     \u001b[0mself\u001b[0m\u001b[1;33m.\u001b[0m\u001b[0m_showtraceback\u001b[0m\u001b[1;33m(\u001b[0m\u001b[0metype\u001b[0m\u001b[1;33m,\u001b[0m \u001b[0mvalue\u001b[0m\u001b[1;33m,\u001b[0m \u001b[0mstb\u001b[0m\u001b[1;33m)\u001b[0m\u001b[1;33m\u001b[0m\u001b[0m\n",
      "\u001b[1;32mc:\\python35\\lib\\site-packages\\IPython\\core\\ultratb.py\u001b[0m in \u001b[0;36mstructured_traceback\u001b[1;34m(self, etype, value, tb, tb_offset, number_of_lines_of_context)\u001b[0m\n\u001b[0;32m   1369\u001b[0m         \u001b[0mself\u001b[0m\u001b[1;33m.\u001b[0m\u001b[0mtb\u001b[0m \u001b[1;33m=\u001b[0m \u001b[0mtb\u001b[0m\u001b[1;33m\u001b[0m\u001b[0m\n\u001b[0;32m   1370\u001b[0m         return FormattedTB.structured_traceback(\n\u001b[1;32m-> 1371\u001b[1;33m             self, etype, value, tb, tb_offset, number_of_lines_of_context)\n\u001b[0m\u001b[0;32m   1372\u001b[0m \u001b[1;33m\u001b[0m\u001b[0m\n\u001b[0;32m   1373\u001b[0m \u001b[1;33m\u001b[0m\u001b[0m\n",
      "\u001b[1;32mc:\\python35\\lib\\site-packages\\IPython\\core\\ultratb.py\u001b[0m in \u001b[0;36mstructured_traceback\u001b[1;34m(self, etype, value, tb, tb_offset, number_of_lines_of_context)\u001b[0m\n\u001b[0;32m   1277\u001b[0m             \u001b[1;31m# Verbose modes need a full traceback\u001b[0m\u001b[1;33m\u001b[0m\u001b[1;33m\u001b[0m\u001b[0m\n\u001b[0;32m   1278\u001b[0m             return VerboseTB.structured_traceback(\n\u001b[1;32m-> 1279\u001b[1;33m                 \u001b[0mself\u001b[0m\u001b[1;33m,\u001b[0m \u001b[0metype\u001b[0m\u001b[1;33m,\u001b[0m \u001b[0mvalue\u001b[0m\u001b[1;33m,\u001b[0m \u001b[0mtb\u001b[0m\u001b[1;33m,\u001b[0m \u001b[0mtb_offset\u001b[0m\u001b[1;33m,\u001b[0m \u001b[0mnumber_of_lines_of_context\u001b[0m\u001b[1;33m\u001b[0m\u001b[0m\n\u001b[0m\u001b[0;32m   1280\u001b[0m             )\n\u001b[0;32m   1281\u001b[0m         \u001b[1;32melse\u001b[0m\u001b[1;33m:\u001b[0m\u001b[1;33m\u001b[0m\u001b[0m\n",
      "\u001b[1;32mc:\\python35\\lib\\site-packages\\IPython\\core\\ultratb.py\u001b[0m in \u001b[0;36mstructured_traceback\u001b[1;34m(self, etype, evalue, etb, tb_offset, number_of_lines_of_context)\u001b[0m\n\u001b[0;32m   1138\u001b[0m             \u001b[0mexception\u001b[0m \u001b[1;33m=\u001b[0m \u001b[0mself\u001b[0m\u001b[1;33m.\u001b[0m\u001b[0mget_parts_of_chained_exception\u001b[0m\u001b[1;33m(\u001b[0m\u001b[0mevalue\u001b[0m\u001b[1;33m)\u001b[0m\u001b[1;33m\u001b[0m\u001b[0m\n\u001b[0;32m   1139\u001b[0m             \u001b[1;32mif\u001b[0m \u001b[0mexception\u001b[0m\u001b[1;33m:\u001b[0m\u001b[1;33m\u001b[0m\u001b[0m\n\u001b[1;32m-> 1140\u001b[1;33m                 \u001b[0mformatted_exceptions\u001b[0m \u001b[1;33m+=\u001b[0m \u001b[0mself\u001b[0m\u001b[1;33m.\u001b[0m\u001b[0mprepare_chained_exception_message\u001b[0m\u001b[1;33m(\u001b[0m\u001b[0mevalue\u001b[0m\u001b[1;33m.\u001b[0m\u001b[0m__cause__\u001b[0m\u001b[1;33m)\u001b[0m\u001b[1;33m\u001b[0m\u001b[0m\n\u001b[0m\u001b[0;32m   1141\u001b[0m                 \u001b[0metype\u001b[0m\u001b[1;33m,\u001b[0m \u001b[0mevalue\u001b[0m\u001b[1;33m,\u001b[0m \u001b[0metb\u001b[0m \u001b[1;33m=\u001b[0m \u001b[0mexception\u001b[0m\u001b[1;33m\u001b[0m\u001b[0m\n\u001b[0;32m   1142\u001b[0m             \u001b[1;32melse\u001b[0m\u001b[1;33m:\u001b[0m\u001b[1;33m\u001b[0m\u001b[0m\n",
      "\u001b[1;31mTypeError\u001b[0m: Can't convert 'list' object to str implicitly"
     ]
    }
   ],
   "source": [
    "import re\n",
    "for i in range(0, len(df1[\"EDIDescription\"])):\n",
    "    s=df1[\"EDIDescription\"][i]\n",
    "    k=re.search(r'{(.*?)}', s).group(1)\n",
    "    df=k+str(df1[\"LineItemNumber\"][i])\n",
    "    df=df.strip(\"#\")\n",
    "    df1['UID'][i]=df\n",
    "\n",
    "    \n",
    "print(df1)\n",
    "\n",
    "df1.to_excel(\"Quick Quote-20191025T162809Z-001/B1.xlsx\",index=False)\n"
   ]
  },
  {
   "cell_type": "code",
   "execution_count": null,
   "metadata": {
    "collapsed": true
   },
   "outputs": [],
   "source": []
  }
 ],
 "metadata": {
  "kernelspec": {
   "display_name": "Python 3",
   "language": "python",
   "name": "python3"
  },
  "language_info": {
   "codemirror_mode": {
    "name": "ipython",
    "version": 3
   },
   "file_extension": ".py",
   "mimetype": "text/x-python",
   "name": "python",
   "nbconvert_exporter": "python",
   "pygments_lexer": "ipython3",
   "version": "3.5.2"
  }
 },
 "nbformat": 4,
 "nbformat_minor": 2
}
